2024-04-25 20:45:36,866 FILE: creds.py IN: create_new_token MESSAGE: Ошибка получения iam_token: HTTPConnectionPool(host='169.254.169.254', port=80): Max retries exceeded with url: /computeMetadata/v1/instance/service-accounts/default/token (Caused by ConnectTimeoutError(<urllib3.connection.HTTPConnection object at 0x0000023364776930>, 'Connection to 169.254.169.254 timed out. (connect timeout=None)'))
